<?xml version="1.0" ?>
<robot name="mini_cheetah" xmlns:xacro="http://ros.org/wiki/xacro">
    <link name="base">
        <inertial>
            <mass value="3.3"/>
            <origin xyz="0.0 0.0 0.0"/>
            <inertia ixx="0.011253" ixy="0" ixz="0" iyy="0.036203" iyz="0" izz="0.042673"/>
        </inertial>
        <visual>
            <geometry>
                <mesh filename="meshes/mini_body.obj"/>
            </geometry>
            <origin rpy="0.0 0.0 0.0" xyz="0.0 0.0 0.0"/>
        </visual>
        <collision>
            <geometry>
                <mesh filename="meshes/mini_body.obj"/>
            </geometry>
            <origin rpy="0 0 0" xyz="0 0 0"/>
        </collision>
    </link>


 
<!--!!!!!!!!!!!! Front Left Leg !!!!!!!!!!!!!!!!!!!!!!!!!!!!!!!!!!!!-->
    <joint name="FL_hip_joint" type="continuous">
        <axis xyz="1 0 0"/>
        <origin rpy="0 0 0" xyz="0.19 0.049 0.0"/>
        <parent link="base"/>
        <child link="FL_hip"/>
    </joint>
    <link name="FL_hip">
        <inertial>
            <mass value="0.54"/>
            <origin xyz="0.0 0.036 0."/>
            <inertia ixx="0.000381" ixy="0.000058" ixz="0.00000045" 
                iyy="0.000560" iyz="0.00000095" izz="0.000444"/>
        </inertial>
        <visual>
            <geometry>
                <mesh filename="meshes/mini_abad.obj"/>
            </geometry>
            <origin rpy="0. 0. -1.5708" xyz="-0.055 0.0 0.0"/>
        </visual>
        <collision>
            <geometry>
                <mesh filename="meshes/mini_abad.obj"/>
            </geometry>
            <origin rpy="0 0 -1.5708" xyz="-0.055 0 0"/>
        </collision>
    </link>

    <joint name="FL_thigh_joint" type="continuous">
        <axis xyz="0 -1 0"/>
        <origin rpy="0.0 0.0 0.0" xyz="0.0 0.062 0.00"/>
        <parent link="FL_hip"/>
        <child link="FL_thigh"/>
    </joint>
    <link name="FL_thigh">
        <inertial>
            <mass value="0.634"/>
            <origin xyz="0.0 0.016 -0.02"/>
            <inertia ixx="0.001983" ixy="0" ixz="0" 
                iyy="0.002103" iyz="0" izz="0.000408"/>
        </inertial>
        <visual>
            <geometry>
                <mesh filename="meshes/mini_upper_link.obj"/>
            </geometry>
            <origin rpy="0.0 -1.5708 0.0" xyz="0.0 0.0 0.0"/>
        </visual>
        <collision>
            <geometry>
                <mesh filename="meshes/mini_upper_link.obj"/>
            </geometry>
            <origin rpy="0 -1.5708 0" xyz="0 0 0"/>
        </collision>
    </link>

    <joint name="FL_calf_joint" type="continuous">
        <axis xyz="0 -1 0"/>
        <origin rpy="0.0 0 0.0" xyz="0.0 0.0 -0.209"/>
        <parent link="FL_thigh"/>
        <child link="FL_calf"/>
    </joint>
    <link name="FL_calf">
        <inertial>
            <mass value="0.064"/>
            <origin xyz="0.0 0.0 -0.209"/>
            <inertia ixx="0.000245" ixy="0" ixz="0.0" iyy="0.000248" iyz="0" izz="0.000006"/>
        </inertial>
        <visual>
            <geometry>
                <mesh filename="meshes/mini_lower_link.obj"/>
            </geometry>
            <origin rpy="0.0 3.141592 0.0" xyz="0.0 0.0 0.0"/>
        </visual>
        <collision>
            <geometry>
                <mesh filename="meshes/mini_lower_link.obj"/>
            </geometry>
            <origin rpy="0 3.141592 0" xyz="0 0 0"/>
        </collision>
    </link>
    <link name="FL_foot">
      <contact>
      <friction_anchor/>
      <stiffness value="30000.0"/>
      <damping value="1000.0"/>
      <spinning_friction value="0.3"/>
      <lateral_friction value="3.0"/>
    </contact>
    <visual>
      <origin rpy="0 0 0" xyz="0 0 0"/>
      <geometry>
        <sphere radius="0.015"/>
      </geometry>
      <material name="darkgray"/>
    </visual>
    <collision>
      <origin rpy="0 0 0" xyz="0 0 0"/>
      <geometry>
        <sphere radius="0.015"/>
      </geometry>
    </collision>
    <inertial>
      <mass value="0.15"/>
      <inertia ixx="0.000025" ixy="0" ixz="0" iyy="0.000025" iyz="0" izz="0.000025"/>
    </inertial>
  </link>
  <joint name="FL_foot_fixed" type="fixed">
    <parent link="FL_calf"/>
    <child link="FL_foot"/>
    <origin xyz="0 0 -0.18"/>
    <dynamics damping="0.0" friction="0.0"/>
  </joint>


    <!--!!!!!!!!!!!! Front Right Leg !!!!!!!!!!!!!!!!!!!!!!!!!!!!!!!!!!!!-->
    <joint name="FR_hip_joint" type="continuous">
        <axis xyz="1 0 0"/>
        <origin rpy="0 0 0" xyz="0.19 -0.049 0.0"/>
        <parent link="base"/>
        <child link="FR_hip"/>
    </joint>
    <link name="FR_hip">
        <inertial>
            <mass value="0.54"/>
            <origin xyz="0.0 -0.036 0."/>
            <inertia ixx="0.000381" ixy="0.000058" ixz="0.00000045" 
                iyy="0.000560" iyz="0.00000095" izz="0.000444"/>
        </inertial>
        <visual>
            <geometry>
                <mesh filename="meshes/mini_abad.obj"/>
            </geometry>
            <origin rpy="3.141592 0.0 1.5708" xyz="-0.055 0.0 0.0"/>
        </visual>
        <collision>
            <geometry>
                <mesh filename="meshes/mini_abad.obj"/>
            </geometry>
            <origin rpy="3.141592 0 1.5708" xyz="-0.055 0 0"/>
        </collision>
    </link>

    <joint name="FR_thigh_joint" type="continuous">
        <axis xyz="0 -1 0"/>
        <origin rpy="0.0 0.0 0.0" xyz="0.0 -0.062 0.00"/>
        <parent link="FR_hip"/>
        <child link="FR_thigh"/>
    </joint>
    <link name="FR_thigh">
        <inertial>
            <mass value="0.634"/>
            <origin xyz="0.0 -0.016 -0.02"/>
            <inertia ixx="0.001983" ixy="0" ixz="0" 
                iyy="0.002103" iyz="0" izz="0.000408"/>
        </inertial>
        <visual>
            <geometry>
                <mesh filename="meshes/mini_upper_link.obj"/>
            </geometry>
            <origin rpy="0.0 -1.5708 0.0" xyz="0.0 0.0 0.0"/>
        </visual>
        <collision>
            <geometry>
                <mesh filename="meshes/mini_upper_link.obj"/>
            </geometry>
            <origin rpy="0 -1.5708 0" xyz="0 0 0"/>
        </collision>
    </link>

    <joint name="FR_calf_joint" type="continuous">
        <axis xyz="0 -1 0"/>
        <origin rpy="0.0 0 0.0" xyz="0.0 0.0 -0.209"/>
        <parent link="FR_thigh"/>
        <child link="FR_calf"/>
    </joint>
    <link name="FR_calf">
        <inertial>
            <mass value="0.064"/>
            <origin xyz="0.0 0.0 -0.209"/>
            <inertia ixx="0.000245" ixy="0" ixz="0.0" iyy="0.000248" iyz="0" izz="0.000006"/>
        </inertial>
        <visual>
            <geometry>
                <mesh filename="meshes/mini_lower_link.obj"/>
            </geometry>
            <origin rpy="0.0 3.141592 0.0" xyz="0.0 0.0 0.0"/>
        </visual>
        <collision>
            <geometry>
                <mesh filename="meshes/mini_lower_link.obj"/>
            </geometry>
            <origin rpy="0 3.141592 0" xyz="0 0 0"/>
        </collision>
    </link>
    <link name="FR_foot">
    <contact>
      <friction_anchor/>
      <stiffness value="30000.0"/>
      <damping value="1000.0"/>
      <spinning_friction value="0.3"/>
      <lateral_friction value="3.0"/>
    </contact>
    <visual>
      <origin rpy="0 0 0" xyz="0 0 0"/>
      <geometry>
        <sphere radius="0.015"/>
      </geometry>
      <material name="darkgray"/>
    </visual>
    <collision>
      <origin rpy="0 0 0" xyz="0 0 0"/>
      <geometry>
        <sphere radius="0.015"/>
      </geometry>
    </collision>
    <inertial>
      <mass value="0.15"/>
      <inertia ixx="0.000025" ixy="0" ixz="0" iyy="0.000025" iyz="0" izz="0.000025"/>
    </inertial>
  </link>
  <joint name="FR_foot_fixed" type="fixed">
    <parent link="FR_calf"/>
    <child link="FR_foot"/>
    <origin xyz="0 0 -0.18"/>
    <dynamics damping="0.0" friction="0.0"/>
  </joint>


<!--!!!!!!!!!!!! Hind Left Leg !!!!!!!!!!!!!!!!!!!!!!!!!!!!!!!!!!!!-->
    <joint name="RL_hip_joint" type="continuous">
        <axis xyz="1 0 0"/>
        <origin rpy="0 0 0" xyz="-0.19 0.049 0.0"/>
        <parent link="base"/>
        <child link="RL_hip"/>
    </joint>
    <link name="RL_hip">
        <inertial>
            <mass value="0.54"/>
            <origin xyz="0.0 0.036 0."/>
            <inertia ixx="0.000381" ixy="0.000058" ixz="0.00000045" 
                iyy="0.000560" iyz="0.00000095" izz="0.000444"/>
        </inertial>
        <visual>
            <geometry>
                <mesh filename="meshes/mini_abad.obj"/>
            </geometry>
            <origin rpy="3.141592 0.0 -1.5708" xyz="0.055 0.0 0.0"/>
        </visual>
        <collision>
            <geometry>
                <mesh filename="meshes/mini_abad.obj"/>
            </geometry>
            <origin rpy="3.141592 0 -1.5708" xyz="0.055 0 0"/>
        </collision>
    </link>

    <joint name="RL_thigh_joint" type="continuous">
        <axis xyz="0 -1 0"/>
        <origin rpy="0.0 0.0 0.0" xyz="0.0 0.062 0.00"/>
        <parent link="RL_hip"/>
        <child link="RL_thigh"/>
    </joint>
    <link name="RL_thigh">
        <inertial>
            <mass value="0.634"/>
            <origin xyz="0.0 0.016 -0.02"/>
            <inertia ixx="0.001983" ixy="0" ixz="0" 
                iyy="0.002103" iyz="0" izz="0.000408"/>
        </inertial>
        <visual>
            <geometry>
                <mesh filename="meshes/mini_upper_link.obj"/>
            </geometry>
            <origin rpy="0.0 -1.5708 0.0" xyz="0.0 0.0 0.0"/>
        </visual>
        <collision>
            <geometry>
                <mesh filename="meshes/mini_upper_link.obj"/>
            </geometry>
            <origin rpy="0 -1.5708 0" xyz="0 0 0"/>
        </collision>
    </link>

    <joint name="RL_calf_joint" type="continuous">
        <axis xyz="0 -1 0"/>
        <origin rpy="0.0 0 0.0" xyz="0.0 0.0 -0.209"/>
        <parent link="RL_thigh"/>
        <child link="RL_calf"/>
    </joint>
    <link name="RL_calf">
        <inertial>
            <mass value="0.064"/>
            <origin xyz="0.0 0.0 -0.209"/>
            <inertia ixx="0.000245" ixy="0" ixz="0.0" iyy="0.000248" iyz="0" izz="0.000006"/>
        </inertial>
        <visual>
            <geometry>
                <mesh filename="meshes/mini_lower_link.obj"/>
            </geometry>
            <origin rpy="0.0 3.141592 0.0" xyz="0.0 0.0 0.0"/>
        </visual>
        <collision>
            <geometry>
                <mesh filename="meshes/mini_lower_link.obj"/>
            </geometry>
            <origin rpy="0 3.141592 0" xyz="0 0 0"/>
        </collision>
    </link>
    <link name="RL_foot">
      <contact>
      <friction_anchor/>
      <stiffness value="30000.0"/>
      <damping value="1000.0"/>
      <spinning_friction value="0.3"/>
      <lateral_friction value="3.0"/>
    </contact>
    <visual>
      <origin rpy="0 0 0" xyz="0 0 0"/>
      <geometry>
        <sphere radius="0.015"/>
      </geometry>
      <material name="darkgray"/>
    </visual>
    <collision>
      <origin rpy="0 0 0" xyz="0 0 0"/>
      <geometry>
        <sphere radius="0.015"/>
      </geometry>
    </collision>
    <inertial>
      <mass value="0.15"/>
      <inertia ixx="0.000025" ixy="0" ixz="0" iyy="0.000025" iyz="0" izz="0.000025"/>
    </inertial>
  </link>
  <joint name="RL_foot_fixed" type="fixed">
    <parent link="RL_calf"/>
    <child link="RL_foot"/>
    <origin xyz="0 0 -0.18"/>
    <dynamics damping="0.0" friction="0.0"/>
  </joint>


<!--!!!!!!!!!!!! Hind Right Leg !!!!!!!!!!!!!!!!!!!!!!!!!!!!!!!!!!!!-->
    <joint name="RR_hip_joint" type="continuous">
        <axis xyz="1 0 0"/>
        <origin rpy="0 0 0" xyz="-0.19 -0.049 0.0"/>
        <parent link="base"/>
        <child link="RR_hip"/>
    </joint>
    <link name="RR_hip">
        <inertial>
            <mass value="0.54"/>
            <origin xyz="0.0 -0.036 0."/>
            <inertia ixx="0.000381" ixy="0.000058" ixz="0.00000045" 
                iyy="0.000560" iyz="0.00000095" izz="0.000444"/>
        </inertial>
        <visual>
            <geometry>
                <mesh filename="meshes/mini_abad.obj"/>
            </geometry>
            <origin rpy="0.0 0.0 1.5708" xyz="0.055 0.0 0.0"/>
        </visual>
        <collision>
            <geometry>
                <mesh filename="meshes/mini_abad.obj"/>
            </geometry>
            <origin rpy="0 0 1.5708" xyz="0.055 0 0"/>
        </collision>
    </link>

    <joint name="RR_thigh_joint" type="continuous">
        <axis xyz="0 -1 0"/>
        <origin rpy="0.0 0.0 0.0" xyz="0.0 -0.062 0.00"/>
        <parent link="RR_hip"/>
        <child link="RR_thigh"/>
    </joint>
    <link name="RR_thigh">
        <inertial>
            <mass value="0.634"/>
            <origin xyz="0.0 -0.016 -0.02"/>
            <inertia ixx="0.001983" ixy="0" ixz="0" 
                iyy="0.002103" iyz="0" izz="0.000408"/>
        </inertial>
        <visual>
            <geometry>
                <mesh filename="meshes/mini_upper_link.obj"/>
            </geometry>
            <origin rpy="0.0 -1.5708 0.0" xyz="0.0 0.0 0.0"/>
        </visual>
        <collision>
            <geometry>
                <mesh filename="meshes/mini_upper_link.obj"/>
            </geometry>
            <origin rpy="0 -1.5708 0" xyz="0 0 0"/>
        </collision>
    </link>

    <joint name="RR_calf_joint" type="continuous">
        <axis xyz="0 -1 0"/>
        <origin rpy="0.0 0 0.0" xyz="0.0 0.0 -0.209"/>
        <parent link="RR_thigh"/>
        <child link="RR_calf"/>
    </joint>
    <link name="RR_calf">
        <inertial>
            <mass value="0.064"/>
            <origin xyz="0.0 0.0 -0.209"/>
            <inertia ixx="0.000245" ixy="0" ixz="0.0" iyy="0.000248" iyz="0" izz="0.000006"/>
        </inertial>
        <visual>
            <geometry>
                <mesh filename="meshes/mini_lower_link.obj"/>
            </geometry>
            <origin rpy="0.0 3.141592 0.0" xyz="0.0 0.0 0.0"/>
        </visual>
        <collision>
            <geometry>
                <mesh filename="meshes/mini_lower_link.obj"/>
            </geometry>
            <origin rpy="0 3.141592 0" xyz="0 0 0"/>
        </collision>
    </link>
     <link name="RR_foot">
      <contact>
      <friction_anchor/>
      <stiffness value="30000.0"/>
      <damping value="1000.0"/>
      <spinning_friction value="0.3"/>
      <lateral_friction value="3.0"/>
    </contact>
    <visual>
      <origin rpy="0 0 0" xyz="0 0 0"/>
      <geometry>
        <sphere radius="0.015"/>
      </geometry>
      <material name="darkgray"/>
    </visual>
    <collision>
      <origin rpy="0 0 0" xyz="0 0 0"/>
      <geometry>
        <sphere radius="0.015"/>
      </geometry>
    </collision>
    <inertial>
      <mass value="0.15"/>
      <inertia ixx="0.000025" ixy="0" ixz="0" iyy="0.000025" iyz="0" izz="0.000025"/>
    </inertial>
  </link>
  <joint name="RR_foot_fixed" type="fixed">
    <parent link="RR_calf"/>
    <child link="RR_foot"/>
    <origin xyz="0 0 -0.18"/>
    <dynamics damping="0.0" friction="0.0"/>
  </joint>



</robot>
