<?xml version="1.0" ?>
<!-- =================================================================================== -->
<!-- |    This document was autogenerated by xacro from hyqreal.urdf.xacro             | -->
<!-- |    EDITING THIS FILE BY HAND IS NOT RECOMMENDED                                 | -->
<!-- =================================================================================== -->
<robot name="hyqreal" xmlns:xacro="http://ros.org/wiki/xacro">
  <!-- standard distances -->
  <!-- <xacro:property name="d_lr" value="0.414"/>
	<xacro:property name="d_fh" value="0.747"/> -->
  <!-- 0.887 1.4192-->
  <!-- ============================ IMU KVH 1775 ========================
         The xacro macro xacro:kvh_1775_imu describes the KVH 1775 IMU,
         together with its frames of reference.
         The IMU has three axes oriented along the diagonal of the mounting
         screws at the bottom, as described at page 6 of the technical manual.
         These axes have three different origins for the sensing points, one
         per axis. Therefore, we define a common origin which is located at the
         average of these three. For completeness, we include the three exact
         axes as well. -->
  <material name="aluminum">
    <color rgba="0.5 0.5 0.5 1"/>
  </material>
  <material name="black">
    <color rgba="0.0 0.0 0.0 1.0"/>
  </material>
  <material name="blue">
    <color rgba="0.0 0.0 0.8 1.0"/>
  </material>
  <material name="green">
    <color rgba="0.0 0.8 0.0 1.0"/>
  </material>
  <material name="grey">
    <color rgba="0.3 0.3 0.3 0.8"/>
  </material>
  <material name="silver">
    <color rgba="0.913725490196 0.913725490196 0.847058823529 1.0"/>
  </material>
  <material name="orange">
    <color rgba="1.0 0.423529411765 0.0392156862745 1.0"/>
  </material>
  <material name="brown">
    <color rgba="0.870588235294 0.811764705882 0.764705882353 1.0"/>
  </material>
  <material name="red">
    <color rgba="0.8 0.0 0.0 1.0"/>
  </material>
  <material name="white">
    <color rgba="1.0 1.0 1.0 1.0"/>
  </material>
  <!--xacro:include filename="$(find sensors_description)/urdfs/sensors/vlp16.urdf.xacro"/-->
  
  <!-- Floating-base Joint -->
  <link name="base">
    <visual>
      <origin rpy="0 0 0" xyz="0 0 0"/>
      <geometry>
        <box size="0.001 0.001 0.001"/>
      </geometry>
    </visual>
  </link>
  <joint name="floating_base" type="fixed">
    <origin rpy="0 0 0" xyz="0 0 0"/>
    <parent link="base"/>
    <child link="trunk"/>
  </joint>
  <!-- Trunk link -->
  <link name="trunk">
    <inertial>
      <origin xyz="-0.015 -0.00186 -0.03465"/>
      <mass value="59"/>
      <inertia ixx="1.498728" ixy="-0.007369" ixz="-0.189135" iyy="9.492381" iyz="0.000185" izz="9.012359"/>
    </inertial>
    <visual>
      <origin rpy="0 0 3.14159265359" xyz="0 0 0"/>
      <geometry>
        <mesh filename="meshes/trunk/combined_torso.dae" scale="0.001 0.001 0.001"/>
      </geometry>
      <material name="grey"/>
    </visual>
    <collision>
      <origin rpy="0 0 3.14159265359" xyz="0 0 0"/>
      <geometry>
        <mesh filename="meshes/trunk/combined_torso_decimated.obj" scale="0.001 0.001 0.001"/>
      </geometry>
    </collision>
  </link>

  <!-- Joints -->
  <!-- hip joint -->
  <joint name="FL_hip_joint" type="revolute">
    <origin rpy="3.14159265359 1.57079632679 0" xyz="0.4435 0.139 0"/>
    <parent link="trunk"/>
    <child link="FL_hip"/>
    <axis xyz="0 0 1"/>
    <dynamics damping="0.1" friction="0"/>
    <limit effort="173.0" lower="-0.733038285838" upper="0.401425727959" velocity="12.0"/>
    <safety_controller k_position="50" k_velocity="10" soft_lower_limit="-0.733038285838" soft_upper_limit="0.401425727959"/>
  </joint>
  <!-- HFE joint -->
  <joint name="FL_thigh_joint" type="revolute">
    <origin rpy="1.57079632679 0 0" xyz="0 -0.117 0"/>
    <parent link="FL_hip"/>
    <child link="FL_thigh"/>
    <axis xyz="0 0 1"/>
    <dynamics damping="0.1" friction="0"/>
    <limit effort="208" lower="0.261799387799" upper="2.18166156499" velocity="12.0"/>
    <safety_controller k_position="50" k_velocity="10" soft_lower_limit="0.261799387799" soft_upper_limit="2.18166156499"/>
  </joint>
  <!-- KFE joint -->
  <joint name="FL_calf_joint" type="revolute">
    <origin rpy="0 0 0" xyz="0.36 0 0"/>
    <parent link="FL_thigh"/>
    <child link="FL_calf"/>
    <axis xyz="0 0 1"/>
    <dynamics damping="0.1" friction="0"/>
    <limit effort="249" lower="-2.77001205584" upper="-0.669857366915" velocity="12.0"/>
    <safety_controller k_position="50.0" k_velocity="10.0" soft_lower_limit="-2.77001205584" soft_upper_limit="-0.669857366915"/>
  </joint>
  <!-- Foot joint -->
  <joint name="FL_foot_fixed" type="fixed">
    <origin rpy="1.57079632679 0 -1.57079632679" xyz="0.38 0 0"/>
    <parent link="FL_calf"/>
    <child link="FL_foot"/>
  </joint>
  <!-- Links -->
  <!-- Hip assembly link -->
  <link name="FL_hip">
    <inertial>
      <origin xyz="-0.010027 -0.010608 0.003644"/>
      <mass value="4.973275"/>
      <inertia ixx="0.011231" ixy="-0.000592" ixz="0.000225" iyy="0.015768" iyz="0.000224" izz="0.016863"/>
    </inertial>
    <visual>
      <origin rpy="0 -1.57079632679 -1.57079632679" xyz="0 -0.046 0"/>
      <geometry>
         --&gt;
				
        <cylinder length="0.117" radius="0.0444"/>
      </geometry>
      <material name="grey"/>
    </visual>
  </link>
  <!-- Upper leg link -->
  <link name="FL_thigh">
    <inertial>
      <origin xyz="0.107987 -0.011459 -0.002121"/>
      <mass value="5.877927"/>
      <inertia ixx="0.016432" ixy="0.001863" ixz="0.003897" iyy="0.075737" iyz="-0.00024" izz="0.079267"/>
    </inertial>
    <visual>
      <origin rpy="0 0 0" xyz="0 0 0"/>
      <geometry>
        <mesh filename="meshes/leg/upperleg.dae" scale="0.001 0.001 0.001"/>
      </geometry>
      <material name="grey"/>
    </visual>
    <collision>
      <origin rpy="0 0 0" xyz="0 0 0"/>
      <geometry>
        <mesh filename="meshes/leg/upperleg.obj" scale="0.001 0.001 0.001"/>
      </geometry>
    </collision>
  </link>
  <!-- Lower leg link -->
  <link name="FL_calf">
    <inertial>
      <origin xyz="0.149302 -0.003801 -0.000624"/>
      <mass value="1.291954"/>
      <inertia ixx="0.001088" ixy="-0.000572" ixz="0.000118" iyy="0.029215" iyz="0.00046" izz="0.029772"/>
    </inertial>
    <visual>
      <origin rpy="0 0 0" xyz="0 0 0"/>
      <geometry>
        <mesh filename="meshes/leg/lowerleg.dae" scale="0.001 0.001 0.001"/>
      </geometry>
      <material name="white"/>
    </visual>
    <collision>
      <origin rpy="0 0 0" xyz="0 0 0"/>
      <geometry>
        <mesh filename="meshes/leg/lowerleg_decimated.obj" scale="0.001 0.001 0.001"/>
      </geometry>
    </collision>
  </link>
  <!-- Foot link -->
  <link name="FL_foot">
    <visual>
      <origin rpy="0.0 0.0 0.0" xyz="0.0 0.0 0.0"/>
      <geometry>
        <sphere radius="0.032"/>
      </geometry>
      <material name="black"/>
    </visual>
    <collision>
      <origin rpy="0 0 0" xyz="0 0 0"/>
      <geometry>
        <sphere radius="0.032"/>
      </geometry>
    </collision>
  </link>
  <!-- Hip assembly -->
  <transmission name="FL_hip_trans">
    <type>transmission_interface/SimpleTransmission</type>
    <joint name="FL_hip_joint">
      <hardwareInterface>hardware_interface/EffortJointInterface</hardwareInterface>
    </joint>
    <actuator name="FL_hip_motor">
      <hardwareInterface>hardware_interface/EffortJointInterface</hardwareInterface>
      <mechanicalReduction>1</mechanicalReduction>
    </actuator>
  </transmission>
  <!-- Upper leg -->
  <transmission name="FL_thigh_trans">
    <type>transmission_interface/SimpleTransmission</type>
    <joint name="FL_thigh_joint">
      <hardwareInterface>hardware_interface/EffortJointInterface</hardwareInterface>
    </joint>
    <actuator name="FL_thigh_motor">
      <hardwareInterface>hardware_interface/EffortJointInterface</hardwareInterface>
      <mechanicalReduction>1</mechanicalReduction>
    </actuator>
  </transmission>
  <!-- Lower leg -->
  <transmission name="FL_calf_trans">
    <type>transmission_interface/SimpleTransmission</type>
    <joint name="FL_calf_joint">
      <hardwareInterface>hardware_interface/EffortJointInterface</hardwareInterface>
    </joint>
    <actuator name="FL_calf_motor">
      <hardwareInterface>hardware_interface/EffortJointInterface</hardwareInterface>
      <mechanicalReduction>1</mechanicalReduction>
    </actuator>
  </transmission>

  <!-- Joints -->
  <!-- hip joint -->
  <joint name="FR_hip_joint" type="revolute">
    <origin rpy="0 1.57079632679 0" xyz="0.4435 -0.139 0"/>
    <parent link="trunk"/>
    <child link="FR_hip"/>
    <axis xyz="0 0 1"/>
    <dynamics damping="0.1" friction="0"/>
    <limit effort="173.0" lower="-0.733038285838" upper="0.401425727959" velocity="12.0"/>
    <safety_controller k_position="50" k_velocity="10" soft_lower_limit="-0.733038285838" soft_upper_limit="0.401425727959"/>
  </joint>
  <!-- HFE joint -->
  <joint name="FR_thigh_joint" type="revolute">
    <origin rpy="-1.57079632679 0 0" xyz="0 -0.117 0"/>
    <parent link="FR_hip"/>
    <child link="FR_thigh"/>
    <axis xyz="0 0 1"/>
    <dynamics damping="0.1" friction="0"/>
    <limit effort="208" lower="0.261799387799" upper="2.18166156499" velocity="12.0"/>
    <safety_controller k_position="50" k_velocity="10" soft_lower_limit="0.261799387799" soft_upper_limit="2.18166156499"/>
  </joint>
  <!-- KFE joint -->
  <joint name="FR_calf_joint" type="revolute">
    <origin rpy="0 0 0" xyz="0.36 0 0"/>
    <parent link="FR_thigh"/>
    <child link="FR_calf"/>
    <axis xyz="0 0 1"/>
    <dynamics damping="0.1" friction="0"/>
    <limit effort="249" lower="-2.77001205584" upper="-0.669857366915" velocity="12.0"/>
    <safety_controller k_position="50.0" k_velocity="10.0" soft_lower_limit="-2.77001205584" soft_upper_limit="-0.669857366915"/>
  </joint>
  <!-- Foot joint -->
  <joint name="FR_foot_fixed" type="fixed">
    <origin rpy="1.57079632679 0 -1.57079632679" xyz="0.38 0 0"/>
    <parent link="FR_calf"/>
    <child link="FR_foot"/>
  </joint>
  <!-- Links -->
  <!-- Hip assembly link -->
  <link name="FR_hip">
    <inertial>
      <origin xyz="-0.010027 -0.010608 0.003644"/>
      <mass value="4.973275"/>
      <inertia ixx="0.011231" ixy="-0.000592" ixz="0.000225" iyy="0.015768" iyz="0.000224" izz="0.016863"/>
    </inertial>
    <visual>
      <origin rpy="0 -1.57079632679 -1.57079632679" xyz="0 -0.046 0"/>
      <geometry>
         --&gt;
				
        <cylinder length="0.117" radius="0.0444"/>
      </geometry>
      <material name="grey"/>
    </visual>
  </link>
  <!-- Upper leg link -->
  <link name="FR_thigh">
    <inertial>
      <origin xyz="0.107987 -0.011459 0.002121"/>
      <mass value="5.877927"/>
      <inertia ixx="0.016432" ixy="0.001863" ixz="-0.003897" iyy="0.075737" iyz="0.00024" izz="0.079267"/>
    </inertial>
    <visual>
      <origin rpy="0 0 0" xyz="0 0 0"/>
      <geometry>
        <mesh filename="meshes/leg/upperleg.dae" scale="0.001 0.001 0.001"/>
      </geometry>
      <material name="grey"/>
    </visual>
    <collision>
      <origin rpy="0 0 0" xyz="0 0 0"/>
      <geometry>
        <mesh filename="meshes/leg/upperleg.obj" scale="0.001 0.001 0.001"/>
      </geometry>
      
    </collision>
  </link>
  <!-- Lower leg link -->
  <link name="FR_calf">
    <inertial>
      <origin xyz="0.149302 -0.003801 -0.000624"/>
      <mass value="1.291954"/>
      <inertia ixx="0.001088" ixy="-0.000572" ixz="0.000118" iyy="0.029215" iyz="0.00046" izz="0.029772"/>
    </inertial>
    <visual>
      <origin rpy="0 0 0" xyz="0 0 0"/>
      <geometry>
        <mesh filename="meshes/leg/lowerleg.dae" scale="0.001 0.001 0.001"/>
      </geometry>
      <material name="white"/>
    </visual>
    <collision>
      <origin rpy="0 0 0" xyz="0 0 0"/>
      <geometry>
        <mesh filename="meshes/leg/lowerleg_decimated.obj" scale="0.001 0.001 0.001"/>
      </geometry>
    </collision>
  </link>
  <!-- Foot link -->
  <link name="FR_foot">
    <visual>
      <origin rpy="0.0 0.0 0.0" xyz="0.0 0.0 0.0"/>
      <geometry>
        <sphere radius="0.032"/>
      </geometry>
      <material name="black"/>
    </visual>
    <collision>
      <origin rpy="0 0 0" xyz="0 0 0"/>
      <geometry>
        <sphere radius="0.032"/>
      </geometry>
    </collision>
  </link>
  <!-- Hip assembly -->
  <transmission name="FR_hip_trans">
    <type>transmission_interface/SimpleTransmission</type>
    <joint name="FR_hip_joint">
      <hardwareInterface>hardware_interface/EffortJointInterface</hardwareInterface>
    </joint>
    <actuator name="FR_hip_motor">
      <hardwareInterface>hardware_interface/EffortJointInterface</hardwareInterface>
      <mechanicalReduction>1</mechanicalReduction>
    </actuator>
  </transmission>
  <!-- Upper leg -->
  <transmission name="FR_thigh_trans">
    <type>transmission_interface/SimpleTransmission</type>
    <joint name="FR_thigh_joint">
      <hardwareInterface>hardware_interface/EffortJointInterface</hardwareInterface>
    </joint>
    <actuator name="FR_thigh_motor">
      <hardwareInterface>hardware_interface/EffortJointInterface</hardwareInterface>
      <mechanicalReduction>1</mechanicalReduction>
    </actuator>
  </transmission>
  <!-- Lower leg -->
  <transmission name="FR_calf_trans">
    <type>transmission_interface/SimpleTransmission</type>
    <joint name="FR_calf_joint">
      <hardwareInterface>hardware_interface/EffortJointInterface</hardwareInterface>
    </joint>
    <actuator name="FR_calf_motor">
      <hardwareInterface>hardware_interface/EffortJointInterface</hardwareInterface>
      <mechanicalReduction>1</mechanicalReduction>
    </actuator>
  </transmission>
 
   <!-- Joints -->
  <!-- hip joint -->
  <joint name="RL_hip_joint" type="revolute">
    <origin rpy="3.14159265359 1.57079632679 0" xyz="-0.4435 0.139 0"/>
    <parent link="trunk"/>
    <child link="RL_hip"/>
    <axis xyz="0 0 1"/>
    <dynamics damping="0.1" friction="0"/>
    <limit effort="173.0" lower="-0.733038285838" upper="0.401425727959" velocity="12.0"/>
    <safety_controller k_position="50" k_velocity="10" soft_lower_limit="-0.733038285838" soft_upper_limit="0.401425727959"/>
  </joint>
  <!-- HFE joint -->
  <joint name="RL_thigh_joint" type="revolute">
    <origin rpy="1.57079632679 0 0" xyz="0 -0.117 0"/>
    <parent link="RL_hip"/>
    <child link="RL_thigh"/>
    <axis xyz="0 0 1"/>
    <dynamics damping="0.1" friction="0"/>
    <limit effort="208" lower="0.261799387799" upper="2.18166156499" velocity="12.0"/>
    <safety_controller k_position="50" k_velocity="10" soft_lower_limit="0.261799387799" soft_upper_limit="2.18166156499"/>
  </joint>
  <!-- KFE joint -->
  <joint name="RL_calf_joint" type="revolute">
    <origin rpy="0 0 0" xyz="0.36 0 0"/>
    <parent link="RL_thigh"/>
    <child link="RL_calf"/>
    <axis xyz="0 0 1"/>
    <dynamics damping="0.1" friction="0"/>
    <limit effort="249" lower="-2.77001205584" upper="-0.669857366915" velocity="12.0"/>
    <safety_controller k_position="50.0" k_velocity="10.0" soft_lower_limit="-2.77001205584" soft_upper_limit="-0.669857366915"/>
  </joint>
  <!-- Foot joint -->
  <joint name="RL_foot_fixed" type="fixed">
    <origin rpy="1.57079632679 0 -1.57079632679" xyz="0.38 0 0"/>
    <parent link="RL_calf"/>
    <child link="RL_foot"/>
  </joint>
  <!-- Links -->
  <!-- Hip assembly link -->
  <link name="RL_hip">
    <inertial>
      <origin xyz="-0.010027 -0.010608 0.003644"/>
      <mass value="4.973275"/>
      <inertia ixx="0.011231" ixy="-0.000592" ixz="0.000225" iyy="0.015768" iyz="0.000224" izz="0.016863"/>
    </inertial>
    <visual>
      <origin rpy="0 -1.57079632679 -1.57079632679" xyz="0 -0.046 0"/>
      <geometry>
         --&gt;
				
        <cylinder length="0.117" radius="0.0444"/>
      </geometry>
      <material name="grey"/>
    </visual>
  </link>
  <!-- Upper leg link -->
  <link name="RL_thigh">
    <inertial>
      <origin xyz="0.107987 -0.011459 -0.002121"/>
      <mass value="5.877927"/>
      <inertia ixx="0.016432" ixy="0.001863" ixz="0.003897" iyy="0.075737" iyz="-0.00024" izz="0.079267"/>
    </inertial>
    <visual>
      <origin rpy="0 0 0" xyz="0 0 0"/>
      <geometry>
        <mesh filename="meshes/leg/upperleg.dae" scale="0.001 0.001 0.001"/>
      </geometry>
      <material name="grey"/>
    </visual>
    <collision>
      <origin rpy="0 0 0" xyz="0 0 0"/>
      <geometry>
        <mesh filename="meshes/leg/upperleg.obj" scale="0.001 0.001 0.001"/>
      </geometry>
      
    </collision>
  </link>
  <!-- Lower leg link -->
  <link name="RL_calf">
    <inertial>
      <origin xyz="0.149302 -0.003801 -0.000624"/>
      <mass value="1.291954"/>
      <inertia ixx="0.001088" ixy="-0.000572" ixz="0.000118" iyy="0.029215" iyz="0.00046" izz="0.029772"/>
    </inertial>
    <visual>
      <origin rpy="0 0 0" xyz="0 0 0"/>
      <geometry>
        <mesh filename="meshes/leg/lowerleg.dae" scale="0.001 0.001 0.001"/>
      </geometry>
      <material name="white"/>
    </visual>
    <collision>
      <origin rpy="0 0 0" xyz="0 0 0"/>
      <geometry>
        <mesh filename="meshes/leg/lowerleg_decimated.obj" scale="0.001 0.001 0.001"/>
      </geometry>
    </collision>
  </link>
  <!-- Foot link -->
  <link name="RL_foot">
    <visual>
      <origin rpy="0.0 0.0 0.0" xyz="0.0 0.0 0.0"/>
      <geometry>
        <sphere radius="0.032"/>
      </geometry>
      <material name="black"/>
    </visual>
    <collision>
      <origin rpy="0 0 0" xyz="0 0 0"/>
      <geometry>
        <sphere radius="0.032"/>
      </geometry>
    </collision>
  </link>
  <!-- Hip assembly -->
  <transmission name="RL_hip_trans">
    <type>transmission_interface/SimpleTransmission</type>
    <joint name="RL_hip_joint">
      <hardwareInterface>hardware_interface/EffortJointInterface</hardwareInterface>
    </joint>
    <actuator name="RL_hip_motor">
      <hardwareInterface>hardware_interface/EffortJointInterface</hardwareInterface>
      <mechanicalReduction>1</mechanicalReduction>
    </actuator>
  </transmission>
  <!-- Upper leg -->
  <transmission name="RL_thigh_trans">
    <type>transmission_interface/SimpleTransmission</type>
    <joint name="RL_thigh_joint">
      <hardwareInterface>hardware_interface/EffortJointInterface</hardwareInterface>
    </joint>
    <actuator name="RL_thigh_motor">
      <hardwareInterface>hardware_interface/EffortJointInterface</hardwareInterface>
      <mechanicalReduction>1</mechanicalReduction>
    </actuator>
  </transmission>
  <!-- Lower leg -->
  <transmission name="RL_calf_trans">
    <type>transmission_interface/SimpleTransmission</type>
    <joint name="RL_calf_joint">
      <hardwareInterface>hardware_interface/EffortJointInterface</hardwareInterface>
    </joint>
    <actuator name="RL_calf_motor">
      <hardwareInterface>hardware_interface/EffortJointInterface</hardwareInterface>
      <mechanicalReduction>1</mechanicalReduction>
    </actuator>
  </transmission>
  
  <!-- Joints -->
  <!-- hip joint -->
  <joint name="RR_hip_joint" type="revolute">
    <origin rpy="0 1.57079632679 0" xyz="-0.4435 -0.139 0"/>
    <parent link="trunk"/>
    <child link="RR_hip"/>
    <axis xyz="0 0 1"/>
    <dynamics damping="0.1" friction="0"/>
    <limit effort="173.0" lower="-0.733038285838" upper="0.401425727959" velocity="12.0"/>
    <safety_controller k_position="50" k_velocity="10" soft_lower_limit="-0.733038285838" soft_upper_limit="0.401425727959"/>
  </joint>
  <!-- HFE joint -->
  <joint name="RR_thigh_joint" type="revolute">
    <origin rpy="-1.57079632679 0 0" xyz="0 -0.117 0"/>
    <parent link="RR_hip"/>
    <child link="RR_thigh"/>
    <axis xyz="0 0 1"/>
    <dynamics damping="0.1" friction="0"/>
    <limit effort="208" lower="0.261799387799" upper="2.18166156499" velocity="12.0"/>
    <safety_controller k_position="50" k_velocity="10" soft_lower_limit="0.261799387799" soft_upper_limit="2.18166156499"/>
  </joint>
  <!-- KFE joint -->
  <joint name="RR_calf_joint" type="revolute">
    <origin rpy="0 0 0" xyz="0.36 0 0"/>
    <parent link="RR_thigh"/>
    <child link="RR_calf"/>
    <axis xyz="0 0 1"/>
    <dynamics damping="0.1" friction="0"/>
    <limit effort="249" lower="-2.77001205584" upper="-0.669857366915" velocity="12.0"/>
    <safety_controller k_position="50.0" k_velocity="10.0" soft_lower_limit="-2.77001205584" soft_upper_limit="-0.669857366915"/>
  </joint>
  <!-- Foot joint -->
  <joint name="RR_foot_fixed" type="fixed">
    <origin rpy="1.57079632679 0 -1.57079632679" xyz="0.38 0 0"/>
    <parent link="RR_calf"/>
    <child link="RR_foot"/>
  </joint>
  <!-- Links -->
  <!-- Hip assembly link -->
  <link name="RR_hip">
    <inertial>
      <origin xyz="-0.010027 -0.010608 0.003644"/>
      <mass value="4.973275"/>
      <inertia ixx="0.011231" ixy="-0.000592" ixz="0.000225" iyy="0.015768" iyz="0.000224" izz="0.016863"/>
    </inertial>
    <visual>
      <origin rpy="0 -1.57079632679 -1.57079632679" xyz="0 -0.046 0"/>
      <geometry>
         --&gt;
				
        <cylinder length="0.117" radius="0.0444"/>
      </geometry>
      <material name="grey"/>
    </visual>
  </link>
  <!-- Upper leg link -->
  <link name="RR_thigh">
    <inertial>
      <origin xyz="0.107987 -0.011459 0.002121"/>
      <mass value="5.877927"/>
      <inertia ixx="0.016432" ixy="0.001863" ixz="-0.003897" iyy="0.075737" iyz="0.00024" izz="0.079267"/>
    </inertial>
    <visual>
      <origin rpy="0 0 0" xyz="0 0 0"/>
      <geometry>
        <mesh filename="meshes/leg/upperleg.dae" scale="0.001 0.001 0.001"/>
      </geometry>
      <material name="grey"/>
    </visual>
    <collision>
      <origin rpy="0 0 0" xyz="0 0 0"/>
      <geometry>
        <mesh filename="meshes/leg/upperleg.obj" scale="0.001 0.001 0.001"/>
      </geometry>
    </collision>
  </link>
  <!-- Lower leg link -->
  <link name="RR_calf">
    <inertial>
      <origin xyz="0.149302 -0.003801 -0.000624"/>
      <mass value="1.291954"/>
      <inertia ixx="0.001088" ixy="-0.000572" ixz="0.000118" iyy="0.029215" iyz="0.00046" izz="0.029772"/>
    </inertial>
    <visual>
      <origin rpy="0 0 0" xyz="0 0 0"/>
      <geometry>
        <mesh filename="meshes/leg/lowerleg.dae" scale="0.001 0.001 0.001"/>
      </geometry>
      <material name="white"/>
    </visual>
    <collision>
      <origin rpy="0 0 0" xyz="0 0 0"/>
      <geometry>
        <mesh filename="meshes/leg/lowerleg_decimated.obj" scale="0.001 0.001 0.001"/>
      </geometry>
    </collision>
  </link>
  <!-- Foot link -->
  <link name="RR_foot">
    <visual>
      <origin rpy="0.0 0.0 0.0" xyz="0.0 0.0 0.0"/>
      <geometry>
        <sphere radius="0.032"/>
      </geometry>
      <material name="black"/>
    </visual>
    <collision>
      <origin rpy="0 0 0" xyz="0 0 0"/>
      <geometry>
        <sphere radius="0.032"/>
      </geometry>
    </collision>
  </link>
  <!-- Hip assembly -->
  <transmission name="RR_hip_trans">
    <type>transmission_interface/SimpleTransmission</type>
    <joint name="RR_hip_joint">
      <hardwareInterface>hardware_interface/EffortJointInterface</hardwareInterface>
    </joint>
    <actuator name="RR_hip_motor">
      <hardwareInterface>hardware_interface/EffortJointInterface</hardwareInterface>
      <mechanicalReduction>1</mechanicalReduction>
    </actuator>
  </transmission>
  <!-- Upper leg -->
  <transmission name="RR_thigh_trans">
    <type>transmission_interface/SimpleTransmission</type>
    <joint name="RR_thigh_joint">
      <hardwareInterface>hardware_interface/EffortJointInterface</hardwareInterface>
    </joint>
    <actuator name="RR_thigh_motor">
      <hardwareInterface>hardware_interface/EffortJointInterface</hardwareInterface>
      <mechanicalReduction>1</mechanicalReduction>
    </actuator>
  </transmission>
  <!-- Lower leg -->
  <transmission name="RR_calf_trans">
    <type>transmission_interface/SimpleTransmission</type>
    <joint name="RR_calf_joint">
      <hardwareInterface>hardware_interface/EffortJointInterface</hardwareInterface>
    </joint>
    <actuator name="RR_calf_motor">
      <hardwareInterface>hardware_interface/EffortJointInterface</hardwareInterface>
      <mechanicalReduction>1</mechanicalReduction>
    </actuator>
  </transmission>
  
  
  <!-- Joint connecting the mount point of the IMU to the robot -->
  <joint name="trunk_imu_mount_joint" type="fixed">
    <origin rpy="3.14159265359 0 0" xyz="-0.1098 0 -0.045"/>
    <parent link="trunk"/>
    <child link="trunk_imu_mount"/>
  </joint>
  <!-- Fake joint connecting the mount point of the IMU to the
                     average sensing frame of the IMU -->
  <joint name="trunk_imu_joint" type="fixed">
    <origin rpy="0 0 0" xyz="-0.017066667 -0.013 0.038366667"/>
    <parent link="trunk_imu_mount"/>
    <child link="trunk_imu"/>
  </joint>
  <!-- Fake joint connecting the mount point of the IMU to
                     the sensing point for the x-axis -->
  <joint name="trunk_imu_sensing_point_x_joint" type="fixed">
    <origin rpy="0 0 0" xyz="0 -0.0263 0.0336"/>
    <parent link="trunk_imu_mount"/>
    <child link="trunk_imu_sensing_point_x"/>
  </joint>
  <!-- Fake joint connecting the mount point of the IMU to
                     the sensing point for the x-axis -->
  <joint name="trunk_imu_sensing_point_y_joint" type="fixed">
    <origin rpy="0 0 0" xyz="-0.0256 -0.0121 0.0372"/>
    <parent link="trunk_imu_mount"/>
    <child link="trunk_imu_sensing_point_y"/>
  </joint>
  <!-- Fake joint connecting the mount point of the IMU to
                the sensing point for the x-axis -->
  <joint name="trunk_imu_sensing_point_z_joint" type="fixed">
    <origin rpy="0 0 0" xyz="-0.0256 -0.0006 0.0443"/>
    <parent link="trunk_imu_mount"/>
    <child link="trunk_imu_sensing_point_z"/>
  </joint>
  <!-- Fake link expressing the average sensing reference frame -->
  <link name="trunk_imu">
    <inertial>
      <mass value="0.000"/>
      <origin rpy="0 0 0" xyz="0 0 0"/>
      <inertia ixx="0.00" ixy="0.0" ixz="0.0" iyy="0.00" iyz="0.0" izz="0.00"/>
    </inertial>
    <visual>
      <!-- fake visual to let URDF parser happy -->
      <geometry>
        <sphere radius="0.0005"/>
      </geometry>
    </visual>
  </link>
  <!-- Fake link exactly located at the sensing point for the x-axis -->
  <link name="trunk_imu_sensing_point_x">
    <inertial>
      <mass value="0.000"/>
      <origin rpy="0 0 0" xyz="0 0 0"/>
      <inertia ixx="0.00" ixy="0.0" ixz="0.0" iyy="0.00" iyz="0.0" izz="0.00"/>
    </inertial>
    <visual>
      <!-- fake visual to let URDF parser happy -->
      <geometry>
        <sphere radius="0.0005"/>
      </geometry>
    </visual>
  </link>
  <!-- Fake link expressing the exact sensing point for the y-axis -->
  <link name="trunk_imu_sensing_point_y">
    <inertial>
      <mass value="0.000"/>
      <origin rpy="0 0 0" xyz="0 0 0"/>
      <inertia ixx="0.00" ixy="0.0" ixz="0.0" iyy="0.00" iyz="0.0" izz="0.00"/>
    </inertial>
    <visual>
      <!-- fake visual to let URDF parser happy -->
      <geometry>
        <sphere radius="0.0005"/>
      </geometry>
    </visual>
  </link>
  <!-- Fake link expressing the exact sensing point for the z-axis -->
  <link name="trunk_imu_sensing_point_z">
    <inertial>
      <mass value="0.000"/>
      <origin rpy="0 0 0" xyz="0 0 0"/>
      <inertia ixx="0.00" ixy="0.0" ixz="0.0" iyy="0.00" iyz="0.0" izz="0.00"/>
    </inertial>
    <visual>
      <!-- fake visual to let URDF parser happy -->
      <geometry>
        <sphere radius="0.0005"/>
      </geometry>
    </visual>
  </link>
  <!-- Link -->
  <link name="trunk_imu_mount">
    <inertial>
      <!-- CoM from technical document, rotated by pi/4 -->
      <origin xyz="-0.001697056  -0.001414214  0.0328"/>
      <mass value="0.69"/>
      <!-- izz = 0.5 * 0.69 * (88.9 / 2 / 1000)^2 -->
      <!-- ixx = iyy = 1/12*0.69*(3*(88.9/2000)^2+(73.7/1000)^2) -->
      <inertia ixx="0.000653148" ixy="0.0" ixz="0.0" iyy="0.000653148" iyz="0.0" izz="0.000681652"/>
    </inertial>
    <visual>
      <origin rpy="0 0 0" xyz="0.0 0.0 0.0"/>
      <geometry>
        <mesh filename="sensors_description/meshes/sensors/kvh_1775.dae" scale="1 1 1"/>
      </geometry>
      <material name="aluminium">
        <color rgba="0.35 0.35 0.35 1"/>
      </material>
    </visual>
  </link>

  <!-- camera body, with origin at bottom screw mount -->
  <joint name="realsense/front/trunkcamera_joint" type="fixed">
    <origin rpy="-0.005878588 0.7692766 -0.01176524" xyz="0.6958928 0.01937854 -0.0968919"/>
    <parent link="trunk"/>
    <child link="realsense/front/camera_bottom_screw_frame"/>
  </joint>
  <link name="realsense/front/camera_bottom_screw_frame"/>
  <joint name="realsense/front/camera_link_joint" type="fixed">
    <origin rpy="0 0 0" xyz="0 0.0175 0.0125"/>
    <parent link="realsense/front/camera_bottom_screw_frame"/>
    <child link="realsense/front/camera_link"/>
  </joint>
  <link name="realsense/front/camera_link">
    <visual>
      <origin rpy="1.57079632679 0 1.57079632679" xyz="0.0149 -0.0175 0"/>
      <geometry>
        <!--box size="${d435_cam_width} ${d435_cam_height} ${d435_cam_depth}"/-->
        <mesh filename="realsense2_description/meshes/d435.dae"/>
      </geometry>
      <material name="aluminum"/>
    </visual>
    <collision>
      <!--origin xyz="0.0 0.0 ${r430_cam_height/2}" rpy="0 0 0"/-->
      <origin rpy="0 0 0" xyz="0 -0.0175 0"/>
      <geometry>
        <box size="0.02505 0.09 0.025"/>
      </geometry>
    </collision>
    <!-- The following are not reliable values, and should not be used for modeling -->
    <inertial>
      <mass value="0.07"/>
      <origin xyz="0 0 0"/>
      <inertia ixx="0.003881243" ixy="0.0" ixz="0.0" iyy="0.000498940" iyz="0.0" izz="0.003879257"/>
    </inertial>
  </link>
  <!-- camera depth joints and links -->
  <joint name="realsense/front/camera_depth_joint" type="fixed">
    <origin rpy="0 0 0" xyz="0 0 0"/>
    <parent link="realsense/front/camera_link"/>
    <child link="realsense/front/camera_depth_frame"/>
  </joint>
  <link name="realsense/front/camera_depth_frame"/>
  <joint name="realsense/front/camera_depth_optical_joint" type="fixed">
    <origin rpy="-1.57079632679 0 -1.57079632679" xyz="0 0 0"/>
    <parent link="realsense/front/camera_depth_frame"/>
    <child link="realsense/front/camera_depth_optical_frame"/>
  </joint>
  <link name="realsense/front/camera_depth_optical_frame"/>
  <!-- camera left IR joints and links -->
  <joint name="realsense/front/camera_left_ir_joint" type="fixed">
    <origin rpy="0 0 0" xyz="0 0.0 0"/>
    <parent link="realsense/front/camera_depth_frame"/>
    <child link="realsense/front/camera_left_ir_frame"/>
  </joint>
  <link name="realsense/front/camera_left_ir_frame"/>
  <joint name="realsense/front/camera_left_ir_optical_joint" type="fixed">
    <origin rpy="-1.57079632679 0 -1.57079632679" xyz="0 0 0"/>
    <parent link="realsense/front/camera_left_ir_frame"/>
    <child link="realsense/front/camera_left_ir_optical_frame"/>
  </joint>
  <link name="realsense/front/camera_left_ir_optical_frame"/>
  <!-- camera right IR joints and links -->
  <joint name="realsense/front/camera_right_ir_joint" type="fixed">
    <origin rpy="0 0 0" xyz="0 -0.05 0"/>
    <parent link="realsense/front/camera_depth_frame"/>
    <child link="realsense/front/camera_right_ir_frame"/>
  </joint>
  <link name="realsense/front/camera_right_ir_frame"/>
  <joint name="realsense/front/camera_right_ir_optical_joint" type="fixed">
    <origin rpy="-1.57079632679 0 -1.57079632679" xyz="0 0 0"/>
    <parent link="realsense/front/camera_right_ir_frame"/>
    <child link="realsense/front/camera_right_ir_optical_frame"/>
  </joint>
  <link name="realsense/front/camera_right_ir_optical_frame"/>
  <!-- camera color joints and links -->
  <joint name="realsense/front/camera_color_joint" type="fixed">
    <origin rpy="0 0 0" xyz="0 0.015 0"/>
    <parent link="realsense/front/camera_depth_frame"/>
    <child link="realsense/front/camera_color_frame"/>
  </joint>
  <link name="realsense/front/camera_color_frame"/>
  <joint name="realsense/front/camera_color_optical_joint" type="fixed">
    <origin rpy="-1.57079632679 0 -1.57079632679" xyz="0 0 0"/>
    <parent link="realsense/front/camera_color_frame"/>
    <child link="realsense/front/camera_color_optical_frame"/>
  </joint>
  <link name="realsense/front/camera_color_optical_frame"/>
  
  <!-- camera body, with origin at bottom screw mount -->
  <joint name="realsense/back/trunkcamera_joint" type="fixed">
    <origin rpy="0 0.785398163397 3.14159" xyz="-0.499873 -0.0000425 -0.109535"/>
    <parent link="trunk"/>
    <child link="realsense/back/camera_bottom_screw_frame"/>
  </joint>
  <link name="realsense/back/camera_bottom_screw_frame"/>
  <joint name="realsense/back/camera_link_joint" type="fixed">
    <origin rpy="0 0 0" xyz="0 0.0175 0.0125"/>
    <parent link="realsense/back/camera_bottom_screw_frame"/>
    <child link="realsense/back/camera_link"/>
  </joint>
  <link name="realsense/back/camera_link">
    <visual>
      <origin rpy="1.57079632679 0 1.57079632679" xyz="0.0149 -0.0175 0"/>
      <geometry>
        <!--box size="${d435_cam_width} ${d435_cam_height} ${d435_cam_depth}"/-->
        <mesh filename="realsense2_description/meshes/d435.dae"/>
      </geometry>
      <material name="aluminum"/>
    </visual>
    <collision>
      <!--origin xyz="0.0 0.0 ${r430_cam_height/2}" rpy="0 0 0"/-->
      <origin rpy="0 0 0" xyz="0 -0.0175 0"/>
      <geometry>
        <box size="0.02505 0.09 0.025"/>
      </geometry>
    </collision>
    <!-- The following are not reliable values, and should not be used for modeling -->
    <inertial>
      <mass value="0.07"/>
      <origin xyz="0 0 0"/>
      <inertia ixx="0.003881243" ixy="0.0" ixz="0.0" iyy="0.000498940" iyz="0.0" izz="0.003879257"/>
    </inertial>
  </link>
  <!-- camera depth joints and links -->
  <joint name="realsense/back/camera_depth_joint" type="fixed">
    <origin rpy="0 0 0" xyz="0 0 0"/>
    <parent link="realsense/back/camera_link"/>
    <child link="realsense/back/camera_depth_frame"/>
  </joint>
  <link name="realsense/back/camera_depth_frame"/>
  <joint name="realsense/back/camera_depth_optical_joint" type="fixed">
    <origin rpy="-1.57079632679 0 -1.57079632679" xyz="0 0 0"/>
    <parent link="realsense/back/camera_depth_frame"/>
    <child link="realsense/back/camera_depth_optical_frame"/>
  </joint>
  <link name="realsense/back/camera_depth_optical_frame"/>
  <!-- camera left IR joints and links -->
  <joint name="realsense/back/camera_left_ir_joint" type="fixed">
    <origin rpy="0 0 0" xyz="0 0.0 0"/>
    <parent link="realsense/back/camera_depth_frame"/>
    <child link="realsense/back/camera_left_ir_frame"/>
  </joint>
  <link name="realsense/back/camera_left_ir_frame"/>
  <joint name="realsense/back/camera_left_ir_optical_joint" type="fixed">
    <origin rpy="-1.57079632679 0 -1.57079632679" xyz="0 0 0"/>
    <parent link="realsense/back/camera_left_ir_frame"/>
    <child link="realsense/back/camera_left_ir_optical_frame"/>
  </joint>
  <link name="realsense/back/camera_left_ir_optical_frame"/>
  <!-- camera right IR joints and links -->
  <joint name="realsense/back/camera_right_ir_joint" type="fixed">
    <origin rpy="0 0 0" xyz="0 -0.05 0"/>
    <parent link="realsense/back/camera_depth_frame"/>
    <child link="realsense/back/camera_right_ir_frame"/>
  </joint>
  <link name="realsense/back/camera_right_ir_frame"/>
  <joint name="realsense/back/camera_right_ir_optical_joint" type="fixed">
    <origin rpy="-1.57079632679 0 -1.57079632679" xyz="0 0 0"/>
    <parent link="realsense/back/camera_right_ir_frame"/>
    <child link="realsense/back/camera_right_ir_optical_frame"/>
  </joint>
  <link name="realsense/back/camera_right_ir_optical_frame"/>
  <!-- camera color joints and links -->
  <joint name="realsense/back/camera_color_joint" type="fixed">
    <origin rpy="0 0 0" xyz="0 0.015 0"/>
    <parent link="realsense/back/camera_depth_frame"/>
    <child link="realsense/back/camera_color_frame"/>
  </joint>
  <link name="realsense/back/camera_color_frame"/>
  <joint name="realsense/back/camera_color_optical_joint" type="fixed">
    <origin rpy="-1.57079632679 0 -1.57079632679" xyz="0 0 0"/>
    <parent link="realsense/back/camera_color_frame"/>
    <child link="realsense/back/camera_color_optical_frame"/>
  </joint>
  <link name="realsense/back/camera_color_optical_frame"/>

  <!--xacro:VLP-16 parent="trunk">
		<origin xyz="-0.349709 0.0 0.277910" rpy="0 ${-15*PI/180} 0"/> 
	    </xacro:VLP-16-->
  <!--xacro:new_calibration_plate_xacro parent="FL_calf"-->
  <!--origin xyz="0.393 -0.023 -0.1" rpy="${PI/2} 0 0"/-->
  <!--origin xyz="0.3588117 -0.0304911 -0.2088889" rpy="${PI/2} 0 -0.137881"/>
  </xacro:new_calibration_plate_xacro-->
</robot>

